{
 "cells": [
  {
   "cell_type": "code",
   "execution_count": 1,
   "metadata": {},
   "outputs": [],
   "source": [
    "import sys\n",
    "import os\n",
    "import numpy as np\n",
    "sys.path.append(os.path.join(os.path.abspath(os.path.dirname(\"__file__\")), '..'))\n",
    "from utils import data_handling, model_development\n",
    "import matplotlib.pyplot as plt\n",
    "from ipywidgets import interact"
   ]
  },
  {
   "cell_type": "code",
   "execution_count": 2,
   "metadata": {},
   "outputs": [],
   "source": [
    "##\n",
    "# Configure the model training policy:\n",
    "#\n",
    "model_development.configure_training_policy()"
   ]
  },
  {
   "cell_type": "code",
   "execution_count": 3,
   "metadata": {},
   "outputs": [
    {
     "name": "stdout",
     "output_type": "stream",
     "text": [
      "[(2624, 300, 300), 2624, 2624]\n"
     ]
    },
    {
     "data": {
      "application/vnd.jupyter.widget-view+json": {
       "model_id": "bd87d71554554f66a0ebaf766307abcb",
       "version_major": 2,
       "version_minor": 0
      },
      "text/plain": [
       "interactive(children=(IntSlider(value=0, description='n', max=2623), Output()), _dom_classes=('widget-interactâ€¦"
      ]
     },
     "metadata": {},
     "output_type": "display_data"
    }
   ],
   "source": [
    "##\n",
    "# Load and preprocess data:\n",
    "#\n",
    "cell_images, cell_labels, cell_types = data_handling.load_data_from_file('../data/labels.csv')\n",
    "print([cell_images.shape, len(cell_labels), len(cell_types)])\n",
    "\n",
    "@interact(n = (0, cell_images.shape[0] - 1))\n",
    "def display_data(n = 0):\n",
    "    fig, axs = plt.subplots()\n",
    "    axs.imshow(cell_images[n], cmap = 'gray')\n",
    "    axs.set_title(f'Class: {cell_labels[n]} - Type: {cell_types[n]}')\n",
    "    return None"
   ]
  },
  {
   "cell_type": "code",
   "execution_count": 4,
   "metadata": {},
   "outputs": [],
   "source": [
    "##\n",
    "# Prepare data for model training:\n",
    "#\n",
    "mono_good = data_handling.query_data_by_labels_and_types(data = cell_images, labels = cell_labels, types = cell_types,\n",
    "    filter_by_labels = 0.0, filter_by_types = 'mono')\n",
    "poly_good = data_handling.query_data_by_labels_and_types(data = cell_images, labels = cell_labels, types = cell_types,\n",
    "    filter_by_labels = 0.0, filter_by_types = 'poly')\n",
    "X_train = np.concatenate((mono_good, poly_good), axis = 0)\n",
    "X_train = np.stack((X_train,) * 3, axis = -1)"
   ]
  },
  {
   "cell_type": "raw",
   "metadata": {},
   "source": [
    "##\n",
    "# Train classification model (first phase):\n",
    "#\n",
    "optimizer = model_development.create_optimizer('nadam')\n",
    "cae_vgg19 = \\\n",
    "    model_development.cae_VGG19(input_shape = (300, 300, 3), weights = 'imagenet', freeze_convolutional_base = True, display_model_information = False)\n",
    "\n",
    "history, training_time = model_development.train_reconstruction_model(1, cae_vgg19, optimizer = optimizer,\n",
    "    training_metrics = model_development.ssim_loss, model_name = 'CAE_VGG19', version = '1.00.00_fs',\n",
    "    X = X_train, Y = X_train, \n",
    "    metric_to_monitor = 'val_loss', no_of_epochs = 200, batch_size = 16, validation_split_ratio = 0.2)"
   ]
  },
  {
   "cell_type": "code",
   "execution_count": 5,
   "metadata": {},
   "outputs": [
    {
     "name": "stdout",
     "output_type": "stream",
     "text": [
      "WARNING:tensorflow:Using a while_loop for converting RngReadAndSkip\n",
      "WARNING:tensorflow:Using a while_loop for converting Bitcast\n",
      "WARNING:tensorflow:Using a while_loop for converting Bitcast\n",
      "WARNING:tensorflow:Using a while_loop for converting StatelessRandomUniformV2\n",
      "WARNING:tensorflow:Using a while_loop for converting RngReadAndSkip\n",
      "WARNING:tensorflow:Using a while_loop for converting Bitcast\n",
      "WARNING:tensorflow:Using a while_loop for converting Bitcast\n",
      "WARNING:tensorflow:Using a while_loop for converting StatelessRandomUniformV2\n",
      "WARNING:tensorflow:Using a while_loop for converting ImageProjectiveTransformV3\n",
      "Epoch 1/200\n",
      "WARNING:tensorflow:Using a while_loop for converting RngReadAndSkip\n",
      "WARNING:tensorflow:Using a while_loop for converting Bitcast\n",
      "WARNING:tensorflow:Using a while_loop for converting Bitcast\n",
      "WARNING:tensorflow:Using a while_loop for converting StatelessRandomUniformV2\n",
      "WARNING:tensorflow:Using a while_loop for converting RngReadAndSkip\n",
      "WARNING:tensorflow:Using a while_loop for converting Bitcast\n",
      "WARNING:tensorflow:Using a while_loop for converting Bitcast\n",
      "WARNING:tensorflow:Using a while_loop for converting StatelessRandomUniformV2\n",
      "WARNING:tensorflow:Using a while_loop for converting ImageProjectiveTransformV3\n",
      "WARNING:tensorflow:Using a while_loop for converting RngReadAndSkip\n",
      "WARNING:tensorflow:Using a while_loop for converting Bitcast\n",
      "WARNING:tensorflow:Using a while_loop for converting Bitcast\n",
      "WARNING:tensorflow:Using a while_loop for converting StatelessRandomUniformV2\n",
      "WARNING:tensorflow:Using a while_loop for converting RngReadAndSkip\n",
      "WARNING:tensorflow:Using a while_loop for converting Bitcast\n",
      "WARNING:tensorflow:Using a while_loop for converting Bitcast\n",
      "WARNING:tensorflow:Using a while_loop for converting StatelessRandomUniformV2\n",
      "WARNING:tensorflow:Using a while_loop for converting ImageProjectiveTransformV3\n",
      " 1/76 [..............................] - ETA: 30:14 - loss: 0.2262"
     ]
    },
    {
     "ename": "ResourceExhaustedError",
     "evalue": "Graph execution error:\n\nDetected at node 'model/conv2d_transpose_4/conv2d_transpose' defined at (most recent call last):\n    File \"c:\\ProgramData\\Anaconda3\\envs\\tensorflow_latest\\lib\\runpy.py\", line 196, in _run_module_as_main\n      return _run_code(code, main_globals, None,\n    File \"c:\\ProgramData\\Anaconda3\\envs\\tensorflow_latest\\lib\\runpy.py\", line 86, in _run_code\n      exec(code, run_globals)\n    File \"c:\\ProgramData\\Anaconda3\\envs\\tensorflow_latest\\lib\\site-packages\\ipykernel_launcher.py\", line 17, in <module>\n      app.launch_new_instance()\n    File \"c:\\ProgramData\\Anaconda3\\envs\\tensorflow_latest\\lib\\site-packages\\traitlets\\config\\application.py\", line 846, in launch_instance\n      app.start()\n    File \"c:\\ProgramData\\Anaconda3\\envs\\tensorflow_latest\\lib\\site-packages\\ipykernel\\kernelapp.py\", line 712, in start\n      self.io_loop.start()\n    File \"c:\\ProgramData\\Anaconda3\\envs\\tensorflow_latest\\lib\\site-packages\\tornado\\platform\\asyncio.py\", line 215, in start\n      self.asyncio_loop.run_forever()\n    File \"c:\\ProgramData\\Anaconda3\\envs\\tensorflow_latest\\lib\\asyncio\\base_events.py\", line 600, in run_forever\n      self._run_once()\n    File \"c:\\ProgramData\\Anaconda3\\envs\\tensorflow_latest\\lib\\asyncio\\base_events.py\", line 1896, in _run_once\n      handle._run()\n    File \"c:\\ProgramData\\Anaconda3\\envs\\tensorflow_latest\\lib\\asyncio\\events.py\", line 80, in _run\n      self._context.run(self._callback, *self._args)\n    File \"c:\\ProgramData\\Anaconda3\\envs\\tensorflow_latest\\lib\\site-packages\\ipykernel\\kernelbase.py\", line 510, in dispatch_queue\n      await self.process_one()\n    File \"c:\\ProgramData\\Anaconda3\\envs\\tensorflow_latest\\lib\\site-packages\\ipykernel\\kernelbase.py\", line 499, in process_one\n      await dispatch(*args)\n    File \"c:\\ProgramData\\Anaconda3\\envs\\tensorflow_latest\\lib\\site-packages\\ipykernel\\kernelbase.py\", line 406, in dispatch_shell\n      await result\n    File \"c:\\ProgramData\\Anaconda3\\envs\\tensorflow_latest\\lib\\site-packages\\ipykernel\\kernelbase.py\", line 730, in execute_request\n      reply_content = await reply_content\n    File \"c:\\ProgramData\\Anaconda3\\envs\\tensorflow_latest\\lib\\site-packages\\ipykernel\\ipkernel.py\", line 383, in do_execute\n      res = shell.run_cell(\n    File \"c:\\ProgramData\\Anaconda3\\envs\\tensorflow_latest\\lib\\site-packages\\ipykernel\\zmqshell.py\", line 528, in run_cell\n      return super().run_cell(*args, **kwargs)\n    File \"c:\\ProgramData\\Anaconda3\\envs\\tensorflow_latest\\lib\\site-packages\\IPython\\core\\interactiveshell.py\", line 2881, in run_cell\n      result = self._run_cell(\n    File \"c:\\ProgramData\\Anaconda3\\envs\\tensorflow_latest\\lib\\site-packages\\IPython\\core\\interactiveshell.py\", line 2936, in _run_cell\n      return runner(coro)\n    File \"c:\\ProgramData\\Anaconda3\\envs\\tensorflow_latest\\lib\\site-packages\\IPython\\core\\async_helpers.py\", line 129, in _pseudo_sync_runner\n      coro.send(None)\n    File \"c:\\ProgramData\\Anaconda3\\envs\\tensorflow_latest\\lib\\site-packages\\IPython\\core\\interactiveshell.py\", line 3135, in run_cell_async\n      has_raised = await self.run_ast_nodes(code_ast.body, cell_name,\n    File \"c:\\ProgramData\\Anaconda3\\envs\\tensorflow_latest\\lib\\site-packages\\IPython\\core\\interactiveshell.py\", line 3338, in run_ast_nodes\n      if await self.run_code(code, result, async_=asy):\n    File \"c:\\ProgramData\\Anaconda3\\envs\\tensorflow_latest\\lib\\site-packages\\IPython\\core\\interactiveshell.py\", line 3398, in run_code\n      exec(code_obj, self.user_global_ns, self.user_ns)\n    File \"C:\\Users\\Admin\\AppData\\Local\\Temp\\ipykernel_17288\\1700096572.py\", line 5, in <cell line: 5>\n      history, training_time = model_development.train_reconstruction_model(2, '../models/weights/CAE_VGG19_1.00.00_fs.hdf5',\n    File \"c:\\Users\\Admin\\Documents\\GitHub\\research.informationsystem.elpv\\notebooks\\..\\utils\\model_development.py\", line 195, in train_reconstruction_model\n      history = model.fit(X, Y, validation_split = validation_split_ratio, epochs = no_of_epochs,\n    File \"c:\\ProgramData\\Anaconda3\\envs\\tensorflow_latest\\lib\\site-packages\\keras\\utils\\traceback_utils.py\", line 64, in error_handler\n      return fn(*args, **kwargs)\n    File \"c:\\ProgramData\\Anaconda3\\envs\\tensorflow_latest\\lib\\site-packages\\keras\\engine\\training.py\", line 1409, in fit\n      tmp_logs = self.train_function(iterator)\n    File \"c:\\ProgramData\\Anaconda3\\envs\\tensorflow_latest\\lib\\site-packages\\keras\\engine\\training.py\", line 1051, in train_function\n      return step_function(self, iterator)\n    File \"c:\\ProgramData\\Anaconda3\\envs\\tensorflow_latest\\lib\\site-packages\\keras\\engine\\training.py\", line 1040, in step_function\n      outputs = model.distribute_strategy.run(run_step, args=(data,))\n    File \"c:\\ProgramData\\Anaconda3\\envs\\tensorflow_latest\\lib\\site-packages\\keras\\engine\\training.py\", line 1030, in run_step\n      outputs = model.train_step(data)\n    File \"c:\\ProgramData\\Anaconda3\\envs\\tensorflow_latest\\lib\\site-packages\\keras\\engine\\training.py\", line 889, in train_step\n      y_pred = self(x, training=True)\n    File \"c:\\ProgramData\\Anaconda3\\envs\\tensorflow_latest\\lib\\site-packages\\keras\\utils\\traceback_utils.py\", line 64, in error_handler\n      return fn(*args, **kwargs)\n    File \"c:\\ProgramData\\Anaconda3\\envs\\tensorflow_latest\\lib\\site-packages\\keras\\engine\\training.py\", line 490, in __call__\n      return super().__call__(*args, **kwargs)\n    File \"c:\\ProgramData\\Anaconda3\\envs\\tensorflow_latest\\lib\\site-packages\\keras\\utils\\traceback_utils.py\", line 64, in error_handler\n      return fn(*args, **kwargs)\n    File \"c:\\ProgramData\\Anaconda3\\envs\\tensorflow_latest\\lib\\site-packages\\keras\\engine\\base_layer.py\", line 1014, in __call__\n      outputs = call_fn(inputs, *args, **kwargs)\n    File \"c:\\ProgramData\\Anaconda3\\envs\\tensorflow_latest\\lib\\site-packages\\keras\\utils\\traceback_utils.py\", line 92, in error_handler\n      return fn(*args, **kwargs)\n    File \"c:\\ProgramData\\Anaconda3\\envs\\tensorflow_latest\\lib\\site-packages\\keras\\engine\\functional.py\", line 458, in call\n      return self._run_internal_graph(\n    File \"c:\\ProgramData\\Anaconda3\\envs\\tensorflow_latest\\lib\\site-packages\\keras\\engine\\functional.py\", line 596, in _run_internal_graph\n      outputs = node.layer(*args, **kwargs)\n    File \"c:\\ProgramData\\Anaconda3\\envs\\tensorflow_latest\\lib\\site-packages\\keras\\utils\\traceback_utils.py\", line 64, in error_handler\n      return fn(*args, **kwargs)\n    File \"c:\\ProgramData\\Anaconda3\\envs\\tensorflow_latest\\lib\\site-packages\\keras\\engine\\base_layer.py\", line 1014, in __call__\n      outputs = call_fn(inputs, *args, **kwargs)\n    File \"c:\\ProgramData\\Anaconda3\\envs\\tensorflow_latest\\lib\\site-packages\\keras\\utils\\traceback_utils.py\", line 92, in error_handler\n      return fn(*args, **kwargs)\n    File \"c:\\ProgramData\\Anaconda3\\envs\\tensorflow_latest\\lib\\site-packages\\keras\\layers\\convolutional\\conv2d_transpose.py\", line 275, in call\n      outputs = backend.conv2d_transpose(\n    File \"c:\\ProgramData\\Anaconda3\\envs\\tensorflow_latest\\lib\\site-packages\\keras\\backend.py\", line 5756, in conv2d_transpose\n      x = tf.compat.v1.nn.conv2d_transpose(x, kernel, output_shape, strides,\nNode: 'model/conv2d_transpose_4/conv2d_transpose'\nDetected at node 'model/conv2d_transpose_4/conv2d_transpose' defined at (most recent call last):\n    File \"c:\\ProgramData\\Anaconda3\\envs\\tensorflow_latest\\lib\\runpy.py\", line 196, in _run_module_as_main\n      return _run_code(code, main_globals, None,\n    File \"c:\\ProgramData\\Anaconda3\\envs\\tensorflow_latest\\lib\\runpy.py\", line 86, in _run_code\n      exec(code, run_globals)\n    File \"c:\\ProgramData\\Anaconda3\\envs\\tensorflow_latest\\lib\\site-packages\\ipykernel_launcher.py\", line 17, in <module>\n      app.launch_new_instance()\n    File \"c:\\ProgramData\\Anaconda3\\envs\\tensorflow_latest\\lib\\site-packages\\traitlets\\config\\application.py\", line 846, in launch_instance\n      app.start()\n    File \"c:\\ProgramData\\Anaconda3\\envs\\tensorflow_latest\\lib\\site-packages\\ipykernel\\kernelapp.py\", line 712, in start\n      self.io_loop.start()\n    File \"c:\\ProgramData\\Anaconda3\\envs\\tensorflow_latest\\lib\\site-packages\\tornado\\platform\\asyncio.py\", line 215, in start\n      self.asyncio_loop.run_forever()\n    File \"c:\\ProgramData\\Anaconda3\\envs\\tensorflow_latest\\lib\\asyncio\\base_events.py\", line 600, in run_forever\n      self._run_once()\n    File \"c:\\ProgramData\\Anaconda3\\envs\\tensorflow_latest\\lib\\asyncio\\base_events.py\", line 1896, in _run_once\n      handle._run()\n    File \"c:\\ProgramData\\Anaconda3\\envs\\tensorflow_latest\\lib\\asyncio\\events.py\", line 80, in _run\n      self._context.run(self._callback, *self._args)\n    File \"c:\\ProgramData\\Anaconda3\\envs\\tensorflow_latest\\lib\\site-packages\\ipykernel\\kernelbase.py\", line 510, in dispatch_queue\n      await self.process_one()\n    File \"c:\\ProgramData\\Anaconda3\\envs\\tensorflow_latest\\lib\\site-packages\\ipykernel\\kernelbase.py\", line 499, in process_one\n      await dispatch(*args)\n    File \"c:\\ProgramData\\Anaconda3\\envs\\tensorflow_latest\\lib\\site-packages\\ipykernel\\kernelbase.py\", line 406, in dispatch_shell\n      await result\n    File \"c:\\ProgramData\\Anaconda3\\envs\\tensorflow_latest\\lib\\site-packages\\ipykernel\\kernelbase.py\", line 730, in execute_request\n      reply_content = await reply_content\n    File \"c:\\ProgramData\\Anaconda3\\envs\\tensorflow_latest\\lib\\site-packages\\ipykernel\\ipkernel.py\", line 383, in do_execute\n      res = shell.run_cell(\n    File \"c:\\ProgramData\\Anaconda3\\envs\\tensorflow_latest\\lib\\site-packages\\ipykernel\\zmqshell.py\", line 528, in run_cell\n      return super().run_cell(*args, **kwargs)\n    File \"c:\\ProgramData\\Anaconda3\\envs\\tensorflow_latest\\lib\\site-packages\\IPython\\core\\interactiveshell.py\", line 2881, in run_cell\n      result = self._run_cell(\n    File \"c:\\ProgramData\\Anaconda3\\envs\\tensorflow_latest\\lib\\site-packages\\IPython\\core\\interactiveshell.py\", line 2936, in _run_cell\n      return runner(coro)\n    File \"c:\\ProgramData\\Anaconda3\\envs\\tensorflow_latest\\lib\\site-packages\\IPython\\core\\async_helpers.py\", line 129, in _pseudo_sync_runner\n      coro.send(None)\n    File \"c:\\ProgramData\\Anaconda3\\envs\\tensorflow_latest\\lib\\site-packages\\IPython\\core\\interactiveshell.py\", line 3135, in run_cell_async\n      has_raised = await self.run_ast_nodes(code_ast.body, cell_name,\n    File \"c:\\ProgramData\\Anaconda3\\envs\\tensorflow_latest\\lib\\site-packages\\IPython\\core\\interactiveshell.py\", line 3338, in run_ast_nodes\n      if await self.run_code(code, result, async_=asy):\n    File \"c:\\ProgramData\\Anaconda3\\envs\\tensorflow_latest\\lib\\site-packages\\IPython\\core\\interactiveshell.py\", line 3398, in run_code\n      exec(code_obj, self.user_global_ns, self.user_ns)\n    File \"C:\\Users\\Admin\\AppData\\Local\\Temp\\ipykernel_17288\\1700096572.py\", line 5, in <cell line: 5>\n      history, training_time = model_development.train_reconstruction_model(2, '../models/weights/CAE_VGG19_1.00.00_fs.hdf5',\n    File \"c:\\Users\\Admin\\Documents\\GitHub\\research.informationsystem.elpv\\notebooks\\..\\utils\\model_development.py\", line 195, in train_reconstruction_model\n      history = model.fit(X, Y, validation_split = validation_split_ratio, epochs = no_of_epochs,\n    File \"c:\\ProgramData\\Anaconda3\\envs\\tensorflow_latest\\lib\\site-packages\\keras\\utils\\traceback_utils.py\", line 64, in error_handler\n      return fn(*args, **kwargs)\n    File \"c:\\ProgramData\\Anaconda3\\envs\\tensorflow_latest\\lib\\site-packages\\keras\\engine\\training.py\", line 1409, in fit\n      tmp_logs = self.train_function(iterator)\n    File \"c:\\ProgramData\\Anaconda3\\envs\\tensorflow_latest\\lib\\site-packages\\keras\\engine\\training.py\", line 1051, in train_function\n      return step_function(self, iterator)\n    File \"c:\\ProgramData\\Anaconda3\\envs\\tensorflow_latest\\lib\\site-packages\\keras\\engine\\training.py\", line 1040, in step_function\n      outputs = model.distribute_strategy.run(run_step, args=(data,))\n    File \"c:\\ProgramData\\Anaconda3\\envs\\tensorflow_latest\\lib\\site-packages\\keras\\engine\\training.py\", line 1030, in run_step\n      outputs = model.train_step(data)\n    File \"c:\\ProgramData\\Anaconda3\\envs\\tensorflow_latest\\lib\\site-packages\\keras\\engine\\training.py\", line 889, in train_step\n      y_pred = self(x, training=True)\n    File \"c:\\ProgramData\\Anaconda3\\envs\\tensorflow_latest\\lib\\site-packages\\keras\\utils\\traceback_utils.py\", line 64, in error_handler\n      return fn(*args, **kwargs)\n    File \"c:\\ProgramData\\Anaconda3\\envs\\tensorflow_latest\\lib\\site-packages\\keras\\engine\\training.py\", line 490, in __call__\n      return super().__call__(*args, **kwargs)\n    File \"c:\\ProgramData\\Anaconda3\\envs\\tensorflow_latest\\lib\\site-packages\\keras\\utils\\traceback_utils.py\", line 64, in error_handler\n      return fn(*args, **kwargs)\n    File \"c:\\ProgramData\\Anaconda3\\envs\\tensorflow_latest\\lib\\site-packages\\keras\\engine\\base_layer.py\", line 1014, in __call__\n      outputs = call_fn(inputs, *args, **kwargs)\n    File \"c:\\ProgramData\\Anaconda3\\envs\\tensorflow_latest\\lib\\site-packages\\keras\\utils\\traceback_utils.py\", line 92, in error_handler\n      return fn(*args, **kwargs)\n    File \"c:\\ProgramData\\Anaconda3\\envs\\tensorflow_latest\\lib\\site-packages\\keras\\engine\\functional.py\", line 458, in call\n      return self._run_internal_graph(\n    File \"c:\\ProgramData\\Anaconda3\\envs\\tensorflow_latest\\lib\\site-packages\\keras\\engine\\functional.py\", line 596, in _run_internal_graph\n      outputs = node.layer(*args, **kwargs)\n    File \"c:\\ProgramData\\Anaconda3\\envs\\tensorflow_latest\\lib\\site-packages\\keras\\utils\\traceback_utils.py\", line 64, in error_handler\n      return fn(*args, **kwargs)\n    File \"c:\\ProgramData\\Anaconda3\\envs\\tensorflow_latest\\lib\\site-packages\\keras\\engine\\base_layer.py\", line 1014, in __call__\n      outputs = call_fn(inputs, *args, **kwargs)\n    File \"c:\\ProgramData\\Anaconda3\\envs\\tensorflow_latest\\lib\\site-packages\\keras\\utils\\traceback_utils.py\", line 92, in error_handler\n      return fn(*args, **kwargs)\n    File \"c:\\ProgramData\\Anaconda3\\envs\\tensorflow_latest\\lib\\site-packages\\keras\\layers\\convolutional\\conv2d_transpose.py\", line 275, in call\n      outputs = backend.conv2d_transpose(\n    File \"c:\\ProgramData\\Anaconda3\\envs\\tensorflow_latest\\lib\\site-packages\\keras\\backend.py\", line 5756, in conv2d_transpose\n      x = tf.compat.v1.nn.conv2d_transpose(x, kernel, output_shape, strides,\nNode: 'model/conv2d_transpose_4/conv2d_transpose'\n2 root error(s) found.\n  (0) RESOURCE_EXHAUSTED:  OOM when allocating tensor with shape[16,64,512,512] and type float on /job:localhost/replica:0/task:0/device:GPU:0 by allocator GPU_0_bfc\n\t [[{{node model/conv2d_transpose_4/conv2d_transpose}}]]\nHint: If you want to see a list of allocated tensors when OOM happens, add report_tensor_allocations_upon_oom to RunOptions for current allocation info. This isn't available when running in Eager mode.\n\n\t [[model/resizing_1/resize/truediv/_228]]\nHint: If you want to see a list of allocated tensors when OOM happens, add report_tensor_allocations_upon_oom to RunOptions for current allocation info. This isn't available when running in Eager mode.\n\n  (1) RESOURCE_EXHAUSTED:  OOM when allocating tensor with shape[16,64,512,512] and type float on /job:localhost/replica:0/task:0/device:GPU:0 by allocator GPU_0_bfc\n\t [[{{node model/conv2d_transpose_4/conv2d_transpose}}]]\nHint: If you want to see a list of allocated tensors when OOM happens, add report_tensor_allocations_upon_oom to RunOptions for current allocation info. This isn't available when running in Eager mode.\n\n0 successful operations.\n0 derived errors ignored. [Op:__inference_train_function_7818]",
     "output_type": "error",
     "traceback": [
      "\u001b[1;31m---------------------------------------------------------------------------\u001b[0m",
      "\u001b[1;31mResourceExhaustedError\u001b[0m                    Traceback (most recent call last)",
      "\u001b[1;32mc:\\Users\\Admin\\Documents\\GitHub\\research.informationsystem.elpv\\notebooks\\CAE_VGG19.ipynb Cell 6\u001b[0m in \u001b[0;36m<cell line: 5>\u001b[1;34m()\u001b[0m\n\u001b[0;32m      <a href='vscode-notebook-cell:/c%3A/Users/Admin/Documents/GitHub/research.informationsystem.elpv/notebooks/CAE_VGG19.ipynb#W5sZmlsZQ%3D%3D?line=0'>1</a>\u001b[0m \u001b[39m##\u001b[39;00m\n\u001b[0;32m      <a href='vscode-notebook-cell:/c%3A/Users/Admin/Documents/GitHub/research.informationsystem.elpv/notebooks/CAE_VGG19.ipynb#W5sZmlsZQ%3D%3D?line=1'>2</a>\u001b[0m \u001b[39m# Train classification model (second phase):\u001b[39;00m\n\u001b[0;32m      <a href='vscode-notebook-cell:/c%3A/Users/Admin/Documents/GitHub/research.informationsystem.elpv/notebooks/CAE_VGG19.ipynb#W5sZmlsZQ%3D%3D?line=2'>3</a>\u001b[0m \u001b[39m#\u001b[39;00m\n\u001b[0;32m      <a href='vscode-notebook-cell:/c%3A/Users/Admin/Documents/GitHub/research.informationsystem.elpv/notebooks/CAE_VGG19.ipynb#W5sZmlsZQ%3D%3D?line=3'>4</a>\u001b[0m optimizer \u001b[39m=\u001b[39m model_development\u001b[39m.\u001b[39mcreate_optimizer(\u001b[39m'\u001b[39m\u001b[39madam\u001b[39m\u001b[39m'\u001b[39m)\n\u001b[1;32m----> <a href='vscode-notebook-cell:/c%3A/Users/Admin/Documents/GitHub/research.informationsystem.elpv/notebooks/CAE_VGG19.ipynb#W5sZmlsZQ%3D%3D?line=4'>5</a>\u001b[0m history, training_time \u001b[39m=\u001b[39m model_development\u001b[39m.\u001b[39;49mtrain_reconstruction_model(\u001b[39m2\u001b[39;49m, \u001b[39m'\u001b[39;49m\u001b[39m../models/weights/CAE_VGG19_1.00.00_fs.hdf5\u001b[39;49m\u001b[39m'\u001b[39;49m,\n\u001b[0;32m      <a href='vscode-notebook-cell:/c%3A/Users/Admin/Documents/GitHub/research.informationsystem.elpv/notebooks/CAE_VGG19.ipynb#W5sZmlsZQ%3D%3D?line=5'>6</a>\u001b[0m     optimizer \u001b[39m=\u001b[39;49m optimizer, training_metrics \u001b[39m=\u001b[39;49m model_development\u001b[39m.\u001b[39;49mssim_loss, \n\u001b[0;32m      <a href='vscode-notebook-cell:/c%3A/Users/Admin/Documents/GitHub/research.informationsystem.elpv/notebooks/CAE_VGG19.ipynb#W5sZmlsZQ%3D%3D?line=6'>7</a>\u001b[0m     model_name \u001b[39m=\u001b[39;49m \u001b[39m'\u001b[39;49m\u001b[39mCAE_VGG19\u001b[39;49m\u001b[39m'\u001b[39;49m, version \u001b[39m=\u001b[39;49m \u001b[39m'\u001b[39;49m\u001b[39m1.00.00_ss\u001b[39;49m\u001b[39m'\u001b[39;49m,\n\u001b[0;32m      <a href='vscode-notebook-cell:/c%3A/Users/Admin/Documents/GitHub/research.informationsystem.elpv/notebooks/CAE_VGG19.ipynb#W5sZmlsZQ%3D%3D?line=7'>8</a>\u001b[0m     X \u001b[39m=\u001b[39;49m X_train, Y \u001b[39m=\u001b[39;49m X_train, \n\u001b[0;32m      <a href='vscode-notebook-cell:/c%3A/Users/Admin/Documents/GitHub/research.informationsystem.elpv/notebooks/CAE_VGG19.ipynb#W5sZmlsZQ%3D%3D?line=8'>9</a>\u001b[0m     metric_to_monitor \u001b[39m=\u001b[39;49m \u001b[39m'\u001b[39;49m\u001b[39mval_loss\u001b[39;49m\u001b[39m'\u001b[39;49m, no_of_epochs \u001b[39m=\u001b[39;49m \u001b[39m200\u001b[39;49m, batch_size \u001b[39m=\u001b[39;49m \u001b[39m16\u001b[39;49m, validation_split_ratio \u001b[39m=\u001b[39;49m \u001b[39m0.2\u001b[39;49m)\n",
      "File \u001b[1;32mc:\\Users\\Admin\\Documents\\GitHub\\research.informationsystem.elpv\\notebooks\\..\\utils\\model_development.py:195\u001b[0m, in \u001b[0;36mtrain_reconstruction_model\u001b[1;34m(training_phase, model, optimizer, training_metrics, model_name, version, X, Y, metric_to_monitor, no_of_epochs, batch_size, validation_split_ratio)\u001b[0m\n\u001b[0;32m    192\u001b[0m checkpoint \u001b[39m=\u001b[39m ModelCheckpoint(weight_path, monitor \u001b[39m=\u001b[39m metric_to_monitor, \n\u001b[0;32m    193\u001b[0m     verbose \u001b[39m=\u001b[39m \u001b[39m1\u001b[39m, save_best_only \u001b[39m=\u001b[39m \u001b[39mTrue\u001b[39;00m, mode \u001b[39m=\u001b[39m \u001b[39m'\u001b[39m\u001b[39mmin\u001b[39m\u001b[39m'\u001b[39m)\n\u001b[0;32m    194\u001b[0m callbacks_list \u001b[39m=\u001b[39m [checkpoint]\n\u001b[1;32m--> 195\u001b[0m history \u001b[39m=\u001b[39m model\u001b[39m.\u001b[39;49mfit(X, Y, validation_split \u001b[39m=\u001b[39;49m validation_split_ratio, epochs \u001b[39m=\u001b[39;49m no_of_epochs, \n\u001b[0;32m    196\u001b[0m     batch_size \u001b[39m=\u001b[39;49m batch_size, callbacks \u001b[39m=\u001b[39;49m callbacks_list, verbose \u001b[39m=\u001b[39;49m \u001b[39m1\u001b[39;49m)\n\u001b[0;32m    197\u001b[0m np\u001b[39m.\u001b[39msave(\u001b[39mf\u001b[39m\u001b[39m'\u001b[39m\u001b[39m../models/history/\u001b[39m\u001b[39m{\u001b[39;00mmodel_name\u001b[39m}\u001b[39;00m\u001b[39m_\u001b[39m\u001b[39m{\u001b[39;00mversion\u001b[39m}\u001b[39;00m\u001b[39m'\u001b[39m, history\u001b[39m.\u001b[39mhistory)\n\u001b[0;32m    198\u001b[0m \u001b[39m###\u001b[39;00m\n",
      "File \u001b[1;32mc:\\ProgramData\\Anaconda3\\envs\\tensorflow_latest\\lib\\site-packages\\keras\\utils\\traceback_utils.py:67\u001b[0m, in \u001b[0;36mfilter_traceback.<locals>.error_handler\u001b[1;34m(*args, **kwargs)\u001b[0m\n\u001b[0;32m     65\u001b[0m \u001b[39mexcept\u001b[39;00m \u001b[39mException\u001b[39;00m \u001b[39mas\u001b[39;00m e:  \u001b[39m# pylint: disable=broad-except\u001b[39;00m\n\u001b[0;32m     66\u001b[0m   filtered_tb \u001b[39m=\u001b[39m _process_traceback_frames(e\u001b[39m.\u001b[39m__traceback__)\n\u001b[1;32m---> 67\u001b[0m   \u001b[39mraise\u001b[39;00m e\u001b[39m.\u001b[39mwith_traceback(filtered_tb) \u001b[39mfrom\u001b[39;00m \u001b[39mNone\u001b[39m\n\u001b[0;32m     68\u001b[0m \u001b[39mfinally\u001b[39;00m:\n\u001b[0;32m     69\u001b[0m   \u001b[39mdel\u001b[39;00m filtered_tb\n",
      "File \u001b[1;32mc:\\ProgramData\\Anaconda3\\envs\\tensorflow_latest\\lib\\site-packages\\tensorflow\\python\\eager\\execute.py:54\u001b[0m, in \u001b[0;36mquick_execute\u001b[1;34m(op_name, num_outputs, inputs, attrs, ctx, name)\u001b[0m\n\u001b[0;32m     52\u001b[0m \u001b[39mtry\u001b[39;00m:\n\u001b[0;32m     53\u001b[0m   ctx\u001b[39m.\u001b[39mensure_initialized()\n\u001b[1;32m---> 54\u001b[0m   tensors \u001b[39m=\u001b[39m pywrap_tfe\u001b[39m.\u001b[39mTFE_Py_Execute(ctx\u001b[39m.\u001b[39m_handle, device_name, op_name,\n\u001b[0;32m     55\u001b[0m                                       inputs, attrs, num_outputs)\n\u001b[0;32m     56\u001b[0m \u001b[39mexcept\u001b[39;00m core\u001b[39m.\u001b[39m_NotOkStatusException \u001b[39mas\u001b[39;00m e:\n\u001b[0;32m     57\u001b[0m   \u001b[39mif\u001b[39;00m name \u001b[39mis\u001b[39;00m \u001b[39mnot\u001b[39;00m \u001b[39mNone\u001b[39;00m:\n",
      "\u001b[1;31mResourceExhaustedError\u001b[0m: Graph execution error:\n\nDetected at node 'model/conv2d_transpose_4/conv2d_transpose' defined at (most recent call last):\n    File \"c:\\ProgramData\\Anaconda3\\envs\\tensorflow_latest\\lib\\runpy.py\", line 196, in _run_module_as_main\n      return _run_code(code, main_globals, None,\n    File \"c:\\ProgramData\\Anaconda3\\envs\\tensorflow_latest\\lib\\runpy.py\", line 86, in _run_code\n      exec(code, run_globals)\n    File \"c:\\ProgramData\\Anaconda3\\envs\\tensorflow_latest\\lib\\site-packages\\ipykernel_launcher.py\", line 17, in <module>\n      app.launch_new_instance()\n    File \"c:\\ProgramData\\Anaconda3\\envs\\tensorflow_latest\\lib\\site-packages\\traitlets\\config\\application.py\", line 846, in launch_instance\n      app.start()\n    File \"c:\\ProgramData\\Anaconda3\\envs\\tensorflow_latest\\lib\\site-packages\\ipykernel\\kernelapp.py\", line 712, in start\n      self.io_loop.start()\n    File \"c:\\ProgramData\\Anaconda3\\envs\\tensorflow_latest\\lib\\site-packages\\tornado\\platform\\asyncio.py\", line 215, in start\n      self.asyncio_loop.run_forever()\n    File \"c:\\ProgramData\\Anaconda3\\envs\\tensorflow_latest\\lib\\asyncio\\base_events.py\", line 600, in run_forever\n      self._run_once()\n    File \"c:\\ProgramData\\Anaconda3\\envs\\tensorflow_latest\\lib\\asyncio\\base_events.py\", line 1896, in _run_once\n      handle._run()\n    File \"c:\\ProgramData\\Anaconda3\\envs\\tensorflow_latest\\lib\\asyncio\\events.py\", line 80, in _run\n      self._context.run(self._callback, *self._args)\n    File \"c:\\ProgramData\\Anaconda3\\envs\\tensorflow_latest\\lib\\site-packages\\ipykernel\\kernelbase.py\", line 510, in dispatch_queue\n      await self.process_one()\n    File \"c:\\ProgramData\\Anaconda3\\envs\\tensorflow_latest\\lib\\site-packages\\ipykernel\\kernelbase.py\", line 499, in process_one\n      await dispatch(*args)\n    File \"c:\\ProgramData\\Anaconda3\\envs\\tensorflow_latest\\lib\\site-packages\\ipykernel\\kernelbase.py\", line 406, in dispatch_shell\n      await result\n    File \"c:\\ProgramData\\Anaconda3\\envs\\tensorflow_latest\\lib\\site-packages\\ipykernel\\kernelbase.py\", line 730, in execute_request\n      reply_content = await reply_content\n    File \"c:\\ProgramData\\Anaconda3\\envs\\tensorflow_latest\\lib\\site-packages\\ipykernel\\ipkernel.py\", line 383, in do_execute\n      res = shell.run_cell(\n    File \"c:\\ProgramData\\Anaconda3\\envs\\tensorflow_latest\\lib\\site-packages\\ipykernel\\zmqshell.py\", line 528, in run_cell\n      return super().run_cell(*args, **kwargs)\n    File \"c:\\ProgramData\\Anaconda3\\envs\\tensorflow_latest\\lib\\site-packages\\IPython\\core\\interactiveshell.py\", line 2881, in run_cell\n      result = self._run_cell(\n    File \"c:\\ProgramData\\Anaconda3\\envs\\tensorflow_latest\\lib\\site-packages\\IPython\\core\\interactiveshell.py\", line 2936, in _run_cell\n      return runner(coro)\n    File \"c:\\ProgramData\\Anaconda3\\envs\\tensorflow_latest\\lib\\site-packages\\IPython\\core\\async_helpers.py\", line 129, in _pseudo_sync_runner\n      coro.send(None)\n    File \"c:\\ProgramData\\Anaconda3\\envs\\tensorflow_latest\\lib\\site-packages\\IPython\\core\\interactiveshell.py\", line 3135, in run_cell_async\n      has_raised = await self.run_ast_nodes(code_ast.body, cell_name,\n    File \"c:\\ProgramData\\Anaconda3\\envs\\tensorflow_latest\\lib\\site-packages\\IPython\\core\\interactiveshell.py\", line 3338, in run_ast_nodes\n      if await self.run_code(code, result, async_=asy):\n    File \"c:\\ProgramData\\Anaconda3\\envs\\tensorflow_latest\\lib\\site-packages\\IPython\\core\\interactiveshell.py\", line 3398, in run_code\n      exec(code_obj, self.user_global_ns, self.user_ns)\n    File \"C:\\Users\\Admin\\AppData\\Local\\Temp\\ipykernel_17288\\1700096572.py\", line 5, in <cell line: 5>\n      history, training_time = model_development.train_reconstruction_model(2, '../models/weights/CAE_VGG19_1.00.00_fs.hdf5',\n    File \"c:\\Users\\Admin\\Documents\\GitHub\\research.informationsystem.elpv\\notebooks\\..\\utils\\model_development.py\", line 195, in train_reconstruction_model\n      history = model.fit(X, Y, validation_split = validation_split_ratio, epochs = no_of_epochs,\n    File \"c:\\ProgramData\\Anaconda3\\envs\\tensorflow_latest\\lib\\site-packages\\keras\\utils\\traceback_utils.py\", line 64, in error_handler\n      return fn(*args, **kwargs)\n    File \"c:\\ProgramData\\Anaconda3\\envs\\tensorflow_latest\\lib\\site-packages\\keras\\engine\\training.py\", line 1409, in fit\n      tmp_logs = self.train_function(iterator)\n    File \"c:\\ProgramData\\Anaconda3\\envs\\tensorflow_latest\\lib\\site-packages\\keras\\engine\\training.py\", line 1051, in train_function\n      return step_function(self, iterator)\n    File \"c:\\ProgramData\\Anaconda3\\envs\\tensorflow_latest\\lib\\site-packages\\keras\\engine\\training.py\", line 1040, in step_function\n      outputs = model.distribute_strategy.run(run_step, args=(data,))\n    File \"c:\\ProgramData\\Anaconda3\\envs\\tensorflow_latest\\lib\\site-packages\\keras\\engine\\training.py\", line 1030, in run_step\n      outputs = model.train_step(data)\n    File \"c:\\ProgramData\\Anaconda3\\envs\\tensorflow_latest\\lib\\site-packages\\keras\\engine\\training.py\", line 889, in train_step\n      y_pred = self(x, training=True)\n    File \"c:\\ProgramData\\Anaconda3\\envs\\tensorflow_latest\\lib\\site-packages\\keras\\utils\\traceback_utils.py\", line 64, in error_handler\n      return fn(*args, **kwargs)\n    File \"c:\\ProgramData\\Anaconda3\\envs\\tensorflow_latest\\lib\\site-packages\\keras\\engine\\training.py\", line 490, in __call__\n      return super().__call__(*args, **kwargs)\n    File \"c:\\ProgramData\\Anaconda3\\envs\\tensorflow_latest\\lib\\site-packages\\keras\\utils\\traceback_utils.py\", line 64, in error_handler\n      return fn(*args, **kwargs)\n    File \"c:\\ProgramData\\Anaconda3\\envs\\tensorflow_latest\\lib\\site-packages\\keras\\engine\\base_layer.py\", line 1014, in __call__\n      outputs = call_fn(inputs, *args, **kwargs)\n    File \"c:\\ProgramData\\Anaconda3\\envs\\tensorflow_latest\\lib\\site-packages\\keras\\utils\\traceback_utils.py\", line 92, in error_handler\n      return fn(*args, **kwargs)\n    File \"c:\\ProgramData\\Anaconda3\\envs\\tensorflow_latest\\lib\\site-packages\\keras\\engine\\functional.py\", line 458, in call\n      return self._run_internal_graph(\n    File \"c:\\ProgramData\\Anaconda3\\envs\\tensorflow_latest\\lib\\site-packages\\keras\\engine\\functional.py\", line 596, in _run_internal_graph\n      outputs = node.layer(*args, **kwargs)\n    File \"c:\\ProgramData\\Anaconda3\\envs\\tensorflow_latest\\lib\\site-packages\\keras\\utils\\traceback_utils.py\", line 64, in error_handler\n      return fn(*args, **kwargs)\n    File \"c:\\ProgramData\\Anaconda3\\envs\\tensorflow_latest\\lib\\site-packages\\keras\\engine\\base_layer.py\", line 1014, in __call__\n      outputs = call_fn(inputs, *args, **kwargs)\n    File \"c:\\ProgramData\\Anaconda3\\envs\\tensorflow_latest\\lib\\site-packages\\keras\\utils\\traceback_utils.py\", line 92, in error_handler\n      return fn(*args, **kwargs)\n    File \"c:\\ProgramData\\Anaconda3\\envs\\tensorflow_latest\\lib\\site-packages\\keras\\layers\\convolutional\\conv2d_transpose.py\", line 275, in call\n      outputs = backend.conv2d_transpose(\n    File \"c:\\ProgramData\\Anaconda3\\envs\\tensorflow_latest\\lib\\site-packages\\keras\\backend.py\", line 5756, in conv2d_transpose\n      x = tf.compat.v1.nn.conv2d_transpose(x, kernel, output_shape, strides,\nNode: 'model/conv2d_transpose_4/conv2d_transpose'\nDetected at node 'model/conv2d_transpose_4/conv2d_transpose' defined at (most recent call last):\n    File \"c:\\ProgramData\\Anaconda3\\envs\\tensorflow_latest\\lib\\runpy.py\", line 196, in _run_module_as_main\n      return _run_code(code, main_globals, None,\n    File \"c:\\ProgramData\\Anaconda3\\envs\\tensorflow_latest\\lib\\runpy.py\", line 86, in _run_code\n      exec(code, run_globals)\n    File \"c:\\ProgramData\\Anaconda3\\envs\\tensorflow_latest\\lib\\site-packages\\ipykernel_launcher.py\", line 17, in <module>\n      app.launch_new_instance()\n    File \"c:\\ProgramData\\Anaconda3\\envs\\tensorflow_latest\\lib\\site-packages\\traitlets\\config\\application.py\", line 846, in launch_instance\n      app.start()\n    File \"c:\\ProgramData\\Anaconda3\\envs\\tensorflow_latest\\lib\\site-packages\\ipykernel\\kernelapp.py\", line 712, in start\n      self.io_loop.start()\n    File \"c:\\ProgramData\\Anaconda3\\envs\\tensorflow_latest\\lib\\site-packages\\tornado\\platform\\asyncio.py\", line 215, in start\n      self.asyncio_loop.run_forever()\n    File \"c:\\ProgramData\\Anaconda3\\envs\\tensorflow_latest\\lib\\asyncio\\base_events.py\", line 600, in run_forever\n      self._run_once()\n    File \"c:\\ProgramData\\Anaconda3\\envs\\tensorflow_latest\\lib\\asyncio\\base_events.py\", line 1896, in _run_once\n      handle._run()\n    File \"c:\\ProgramData\\Anaconda3\\envs\\tensorflow_latest\\lib\\asyncio\\events.py\", line 80, in _run\n      self._context.run(self._callback, *self._args)\n    File \"c:\\ProgramData\\Anaconda3\\envs\\tensorflow_latest\\lib\\site-packages\\ipykernel\\kernelbase.py\", line 510, in dispatch_queue\n      await self.process_one()\n    File \"c:\\ProgramData\\Anaconda3\\envs\\tensorflow_latest\\lib\\site-packages\\ipykernel\\kernelbase.py\", line 499, in process_one\n      await dispatch(*args)\n    File \"c:\\ProgramData\\Anaconda3\\envs\\tensorflow_latest\\lib\\site-packages\\ipykernel\\kernelbase.py\", line 406, in dispatch_shell\n      await result\n    File \"c:\\ProgramData\\Anaconda3\\envs\\tensorflow_latest\\lib\\site-packages\\ipykernel\\kernelbase.py\", line 730, in execute_request\n      reply_content = await reply_content\n    File \"c:\\ProgramData\\Anaconda3\\envs\\tensorflow_latest\\lib\\site-packages\\ipykernel\\ipkernel.py\", line 383, in do_execute\n      res = shell.run_cell(\n    File \"c:\\ProgramData\\Anaconda3\\envs\\tensorflow_latest\\lib\\site-packages\\ipykernel\\zmqshell.py\", line 528, in run_cell\n      return super().run_cell(*args, **kwargs)\n    File \"c:\\ProgramData\\Anaconda3\\envs\\tensorflow_latest\\lib\\site-packages\\IPython\\core\\interactiveshell.py\", line 2881, in run_cell\n      result = self._run_cell(\n    File \"c:\\ProgramData\\Anaconda3\\envs\\tensorflow_latest\\lib\\site-packages\\IPython\\core\\interactiveshell.py\", line 2936, in _run_cell\n      return runner(coro)\n    File \"c:\\ProgramData\\Anaconda3\\envs\\tensorflow_latest\\lib\\site-packages\\IPython\\core\\async_helpers.py\", line 129, in _pseudo_sync_runner\n      coro.send(None)\n    File \"c:\\ProgramData\\Anaconda3\\envs\\tensorflow_latest\\lib\\site-packages\\IPython\\core\\interactiveshell.py\", line 3135, in run_cell_async\n      has_raised = await self.run_ast_nodes(code_ast.body, cell_name,\n    File \"c:\\ProgramData\\Anaconda3\\envs\\tensorflow_latest\\lib\\site-packages\\IPython\\core\\interactiveshell.py\", line 3338, in run_ast_nodes\n      if await self.run_code(code, result, async_=asy):\n    File \"c:\\ProgramData\\Anaconda3\\envs\\tensorflow_latest\\lib\\site-packages\\IPython\\core\\interactiveshell.py\", line 3398, in run_code\n      exec(code_obj, self.user_global_ns, self.user_ns)\n    File \"C:\\Users\\Admin\\AppData\\Local\\Temp\\ipykernel_17288\\1700096572.py\", line 5, in <cell line: 5>\n      history, training_time = model_development.train_reconstruction_model(2, '../models/weights/CAE_VGG19_1.00.00_fs.hdf5',\n    File \"c:\\Users\\Admin\\Documents\\GitHub\\research.informationsystem.elpv\\notebooks\\..\\utils\\model_development.py\", line 195, in train_reconstruction_model\n      history = model.fit(X, Y, validation_split = validation_split_ratio, epochs = no_of_epochs,\n    File \"c:\\ProgramData\\Anaconda3\\envs\\tensorflow_latest\\lib\\site-packages\\keras\\utils\\traceback_utils.py\", line 64, in error_handler\n      return fn(*args, **kwargs)\n    File \"c:\\ProgramData\\Anaconda3\\envs\\tensorflow_latest\\lib\\site-packages\\keras\\engine\\training.py\", line 1409, in fit\n      tmp_logs = self.train_function(iterator)\n    File \"c:\\ProgramData\\Anaconda3\\envs\\tensorflow_latest\\lib\\site-packages\\keras\\engine\\training.py\", line 1051, in train_function\n      return step_function(self, iterator)\n    File \"c:\\ProgramData\\Anaconda3\\envs\\tensorflow_latest\\lib\\site-packages\\keras\\engine\\training.py\", line 1040, in step_function\n      outputs = model.distribute_strategy.run(run_step, args=(data,))\n    File \"c:\\ProgramData\\Anaconda3\\envs\\tensorflow_latest\\lib\\site-packages\\keras\\engine\\training.py\", line 1030, in run_step\n      outputs = model.train_step(data)\n    File \"c:\\ProgramData\\Anaconda3\\envs\\tensorflow_latest\\lib\\site-packages\\keras\\engine\\training.py\", line 889, in train_step\n      y_pred = self(x, training=True)\n    File \"c:\\ProgramData\\Anaconda3\\envs\\tensorflow_latest\\lib\\site-packages\\keras\\utils\\traceback_utils.py\", line 64, in error_handler\n      return fn(*args, **kwargs)\n    File \"c:\\ProgramData\\Anaconda3\\envs\\tensorflow_latest\\lib\\site-packages\\keras\\engine\\training.py\", line 490, in __call__\n      return super().__call__(*args, **kwargs)\n    File \"c:\\ProgramData\\Anaconda3\\envs\\tensorflow_latest\\lib\\site-packages\\keras\\utils\\traceback_utils.py\", line 64, in error_handler\n      return fn(*args, **kwargs)\n    File \"c:\\ProgramData\\Anaconda3\\envs\\tensorflow_latest\\lib\\site-packages\\keras\\engine\\base_layer.py\", line 1014, in __call__\n      outputs = call_fn(inputs, *args, **kwargs)\n    File \"c:\\ProgramData\\Anaconda3\\envs\\tensorflow_latest\\lib\\site-packages\\keras\\utils\\traceback_utils.py\", line 92, in error_handler\n      return fn(*args, **kwargs)\n    File \"c:\\ProgramData\\Anaconda3\\envs\\tensorflow_latest\\lib\\site-packages\\keras\\engine\\functional.py\", line 458, in call\n      return self._run_internal_graph(\n    File \"c:\\ProgramData\\Anaconda3\\envs\\tensorflow_latest\\lib\\site-packages\\keras\\engine\\functional.py\", line 596, in _run_internal_graph\n      outputs = node.layer(*args, **kwargs)\n    File \"c:\\ProgramData\\Anaconda3\\envs\\tensorflow_latest\\lib\\site-packages\\keras\\utils\\traceback_utils.py\", line 64, in error_handler\n      return fn(*args, **kwargs)\n    File \"c:\\ProgramData\\Anaconda3\\envs\\tensorflow_latest\\lib\\site-packages\\keras\\engine\\base_layer.py\", line 1014, in __call__\n      outputs = call_fn(inputs, *args, **kwargs)\n    File \"c:\\ProgramData\\Anaconda3\\envs\\tensorflow_latest\\lib\\site-packages\\keras\\utils\\traceback_utils.py\", line 92, in error_handler\n      return fn(*args, **kwargs)\n    File \"c:\\ProgramData\\Anaconda3\\envs\\tensorflow_latest\\lib\\site-packages\\keras\\layers\\convolutional\\conv2d_transpose.py\", line 275, in call\n      outputs = backend.conv2d_transpose(\n    File \"c:\\ProgramData\\Anaconda3\\envs\\tensorflow_latest\\lib\\site-packages\\keras\\backend.py\", line 5756, in conv2d_transpose\n      x = tf.compat.v1.nn.conv2d_transpose(x, kernel, output_shape, strides,\nNode: 'model/conv2d_transpose_4/conv2d_transpose'\n2 root error(s) found.\n  (0) RESOURCE_EXHAUSTED:  OOM when allocating tensor with shape[16,64,512,512] and type float on /job:localhost/replica:0/task:0/device:GPU:0 by allocator GPU_0_bfc\n\t [[{{node model/conv2d_transpose_4/conv2d_transpose}}]]\nHint: If you want to see a list of allocated tensors when OOM happens, add report_tensor_allocations_upon_oom to RunOptions for current allocation info. This isn't available when running in Eager mode.\n\n\t [[model/resizing_1/resize/truediv/_228]]\nHint: If you want to see a list of allocated tensors when OOM happens, add report_tensor_allocations_upon_oom to RunOptions for current allocation info. This isn't available when running in Eager mode.\n\n  (1) RESOURCE_EXHAUSTED:  OOM when allocating tensor with shape[16,64,512,512] and type float on /job:localhost/replica:0/task:0/device:GPU:0 by allocator GPU_0_bfc\n\t [[{{node model/conv2d_transpose_4/conv2d_transpose}}]]\nHint: If you want to see a list of allocated tensors when OOM happens, add report_tensor_allocations_upon_oom to RunOptions for current allocation info. This isn't available when running in Eager mode.\n\n0 successful operations.\n0 derived errors ignored. [Op:__inference_train_function_7818]"
     ]
    }
   ],
   "source": [
    "##\n",
    "# Train classification model (second phase):\n",
    "#\n",
    "optimizer = model_development.create_optimizer('adam')\n",
    "history, training_time = model_development.train_reconstruction_model(2, '../models/weights/CAE_VGG19_1.00.00_fs.hdf5',\n",
    "    optimizer = optimizer, training_metrics = model_development.ssim_loss, \n",
    "    model_name = 'CAE_VGG19', version = '1.00.00_ss',\n",
    "    X = X_train, Y = X_train, \n",
    "    metric_to_monitor = 'val_loss', no_of_epochs = 200, batch_size = 4, validation_split_ratio = 0.2)"
   ]
  }
 ],
 "metadata": {
  "kernelspec": {
   "display_name": "Python 3.10.4 ('tensorflow_latest')",
   "language": "python",
   "name": "python3"
  },
  "language_info": {
   "codemirror_mode": {
    "name": "ipython",
    "version": 3
   },
   "file_extension": ".py",
   "mimetype": "text/x-python",
   "name": "python",
   "nbconvert_exporter": "python",
   "pygments_lexer": "ipython3",
   "version": "3.10.4"
  },
  "orig_nbformat": 4,
  "vscode": {
   "interpreter": {
    "hash": "7d1c19e37e5f6196bc516d7b965f651cc74a678b65e0e3f127f9e9132621bafc"
   }
  }
 },
 "nbformat": 4,
 "nbformat_minor": 2
}
